Workbook
Name Slicer_Category: #N/A
Name Slicer_Payment_Method: #N/A
Name Slicer_Quarter: #N/A
Name Slicer_Status: #N/A

Sheet amazon_sales_data 2025
A1: Order ID | B1: Date | C1: Product | D1: Category | E1: Price | F1: Quantity | G1: Total Sales | H1: Customer Name | I1: Customer Location | J1: Payment Method | K1: Status | L1: Month | M1: Month Number | N1: Quarter | O1: Revenue Bucket | P1: Order Size | Q1: Is Completed | R1: Is Cancelled | S1: Revenue Lost
A2: ORD0001 | B2: 45730 | C2: Running Shoes | D2: Footwear | E2: 60 | F2: 3 | G2: 180 | H2: Emma Clark | I2: New York | J2: Debit Card | K2: Cancelled | L2: =TEXT(B2,"MMMM") -> March | M2: =MONTH(B2) -> 3 | N2: =IF(MONTH(B2)<=3,"Q1",IF(MONTH(B2)<=6,"Q2",IF(MONTH(B2)<=9,"Q3","Q4"))) -> Q1 | O2: =IF(G2>=5000,"High (≥5K)",IF(G2>=2000,"Mid (2K-5K)","Low (<2K)")) -> Low (<2K) | P2: =IF(F2>=5,"Bulk (5+)",IF(F2>=3,"Medium (3-4)","Small (1-2)")) -> Medium (3-4) | Q2: =IF(K2="Completed",1,0) -> 0 | R2: =IF(K2="Cancelled",1,0) -> 1 | S2: =IF(K2="Cancelled",G2,0) -> 180
A3: ORD0002 | B3: 45736 | C3: Headphones | D3: Electronics | E3: 100 | F3: 4 | G3: 400 | H3: Emily Johnson | I3: San Francisco | J3: Debit Card | K3: Pending | L3: =TEXT(B3,"MMMM") -> March | M3: =MONTH(B3) -> 3 | N3: =IF(MONTH(B3)<=3,"Q1",IF(MONTH(B3)<=6,"Q2",IF(MONTH(B3)<=9,"Q3","Q4"))) -> Q1 | O3: =IF(G3>=5000,"High (≥5K)",IF(G3>=2000,"Mid (2K-5K)","Low (<2K)")) -> Low (<2K) | P3: =IF(F3>=5,"Bulk (5+)",IF(F3>=3,"Medium (3-4)","Small (1-2)")) -> Medium (3-4) | Q3: =IF(K3="Completed",1,0) -> 0 | R3: =IF(K3="Cancelled",1,0) -> 0 | S3: =IF(K3="Cancelled",G3,0) -> 0
A4: ORD0003 | B4: 45703 | C4: Running Shoes | D4: Footwear | E4: 60 | F4: 2 | G4: 120 | H4: John Doe | I4: Denver | J4: Amazon Pay | K4: Cancelled | L4: =TEXT(B4,"MMMM") -> February | M4: =MONTH(B4) -> 2 | N4: =IF(MONTH(B4)<=3,"Q1",IF(MONTH(B4)<=6,"Q2",IF(MONTH(B4)<=9,"Q3","Q4"))) -> Q1 | O4: =IF(G4>=5000,"High (≥5K)",IF(G4>=2000,"Mid (2K-5K)","Low (<2K)")) -> Low (<2K) | P4: =IF(F4>=5,"Bulk (5+)",IF(F4>=3,"Medium (3-4)","Small (1-2)")) -> Small (1-2) | Q4: =IF(K4="Completed",1,0) -> 0 | R4: =IF(K4="Cancelled",1,0) -> 1 | S4: =IF(K4="Cancelled",G4,0) -> 120
A5: ORD0004 | B5: 45707 | C5: Running Shoes | D5: Footwear | E5: 60 | F5: 3 | G5: 180 | H5: Olivia Wilson | I5: Dallas | J5: Credit Card | K5: Pending | L5: =TEXT(B5,"MMMM") -> February | M5: =MONTH(B5) -> 2 | N5: =IF(MONTH(B5)<=3,"Q1",IF(MONTH(B5)<=6,"Q2",IF(MONTH(B5)<=9,"Q3","Q4"))) -> Q1 | O5: =IF(G5>=5000,"High (≥5K)",IF(G5>=2000,"Mid (2K-5K)","Low (<2K)")) -> Low (<2K) | P5: =IF(F5>=5,"Bulk (5+)",IF(F5>=3,"Medium (3-4)","Small (1-2)")) -> Medium (3-4) | Q5: =IF(K5="Completed",1,0) -> 0 | R5: =IF(K5="Cancelled",1,0) -> 0 | S5: =IF(K5="Cancelled",G5,0) -> 0
A6: ORD0005 | B6: 45726 | C6: Smartwatch | D6: Electronics | E6: 150 | F6: 3 | G6: 450 | H6: Emma Clark | I6: New York | J6: Debit Card | K6: Pending | L6: =TEXT(B6,"MMMM") -> March | M6: =MONTH(B6) -> 3 | N6: =IF(MONTH(B6)<=3,"Q1",IF(MONTH(B6)<=6,"Q2",IF(MONTH(B6)<=9,"Q3","Q4"))) -> Q1 | O6: =IF(G6>=5000,"High (≥5K)",IF(G6>=2000,"Mid (2K-5K)","Low (<2K)")) -> Low (<2K) | P6: =IF(F6>=5,"Bulk (5+)",IF(F6>=3,"Medium (3-4)","Small (1-2)")) -> Medium (3-4) | Q6: =IF(K6="Completed",1,0) -> 0 | R6: =IF(K6="Cancelled",1,0) -> 0 | S6: =IF(K6="Cancelled",G6,0) -> 0
A7: ORD0006 | B7: 45730 | C7: T-Shirt | D7: Clothing | E7: 20 | F7: 1 | G7: 20 | H7: John Doe | I7: Dallas | J7: Credit Card | K7: Pending | L7: =TEXT(B7,"MMMM") -> March | M7: =MONTH(B7) -> 3 | N7: =IF(MONTH(B7)<=3,"Q1",IF(MONTH(B7)<=6,"Q2",IF(MONTH(B7)<=9,"Q3","Q4"))) -> Q1 | O7: =IF(G7>=5000,"High (≥5K)",IF(G7>=2000,"Mid (2K-5K)","Low (<2K)")) -> Low (<2K) | P7: =IF(F7>=5,"Bulk (5+)",IF(F7>=3,"Medium (3-4)","Small (1-2)")) -> Small (1-2) | Q7: =IF(K7="Completed",1,0) -> 0 | R7: =IF(K7="Cancelled",1,0) -> 0 | S7: =IF(K7="Cancelled",G7,0) -> 0
A8: ORD0007 | B8: 45734 | C8: Smartwatch | D8: Electronics | E8: 150 | F8: 4 | G8: 600 | H8: Emma Clark | I8: Houston | J8: PayPal | K8: Completed | L8: =TEXT(B8,"MMMM") -> March | M8: =MONTH(B8) -> 3 | N8: =IF(MONTH(B8)<=3,"Q1",IF(MONTH(B8)<=6,"Q2",IF(MONTH(B8)<=9,"Q3","Q4"))) -> Q1 | O8: =IF(G8>=5000,"High (≥5K)",IF(G8>=2000,"Mid (2K-5K)","Low (<2K)")) -> Low (<2K) | P8: =IF(F8>=5,"Bulk (5+)",IF(F8>=3,"Medium (3-4)","Small (1-2)")) -> Medium (3-4) | Q8: =IF(K8="Completed",1,0) -> 1 | R8: =IF(K8="Cancelled",1,0) -> 0 | S8: =IF(K8="Cancelled",G8,0) -> 0
A9: ORD0008 | B9: 45718 | C9: Smartphone | D9: Electronics | E9: 500 | F9: 1 | G9: 500 | H9: Sophia Miller | I9: Miami | J9: PayPal | K9: Completed | L9: =TEXT(B9,"MMMM") -> March | M9: =MONTH(B9) -> 3 | N9: =IF(MONTH(B9)<=3,"Q1",IF(MONTH(B9)<=6,"Q2",IF(MONTH(B9)<=9,"Q3","Q4"))) -> Q1 | O9: =IF(G9>=5000,"High (≥5K)",IF(G9>=2000,"Mid (2K-5K)","Low (<2K)")) -> Low (<2K) | P9: =IF(F9>=5,"Bulk (5+)",IF(F9>=3,"Medium (3-4)","Small (1-2)")) -> Small (1-2) | Q9: =IF(K9="Completed",1,0) -> 1 | R9: =IF(K9="Cancelled",1,0) -> 0 | S9: =IF(K9="Cancelled",G9,0) -> 0
A10: ORD0009 | B10: 45724 | C10: T-Shirt | D10: Clothing | E10: 20 | F10: 3 | G10: 60 | H10: Sophia Miller | I10: Boston | J10: PayPal | K10: Completed | L10: =TEXT(B10,"MMMM") -> March | M10: =MONTH(B10) -> 3 | N10: =IF(MONTH(B10)<=3,"Q1",IF(MONTH(B10)<=6,"Q2",IF(MONTH(B10)<=9,"Q3","Q4"))) -> Q1 | O10: =IF(G10>=5000,"High (≥5K)",IF(G10>=2000,"Mid (2K-5K)","Low (<2K)")) -> Low (<2K) | P10: =IF(F10>=5,"Bulk (5+)",IF(F10>=3,"Medium (3-4)","Small (1-2)")) -> Medium (3-4) | Q10: =IF(K10="Completed",1,0) -> 1 | R10: =IF(K10="Cancelled",1,0) -> 0 | S10: =IF(K10="Cancelled",G10,0) -> 0
A11: ORD0010 | B11: 45728 | C11: Smartphone | D11: Electronics | E11: 500 | F11: 1 | G11: 500 | H11: Emily Johnson | I11: San Francisco | J11: Credit Card | K11: Cancelled | L11: =TEXT(B11,"MMMM") -> March | M11: =MONTH(B11) -> 3 | N11: =IF(MONTH(B11)<=3,"Q1",IF(MONTH(B11)<=6,"Q2",IF(MONTH(B11)<=9,"Q3","Q4"))) -> Q1 | O11: =IF(G11>=5000,"High (≥5K)",IF(G11>=2000,"Mid (2K-5K)","Low (<2K)")) -> Low (<2K) | P11: =IF(F11>=5,"Bulk (5+)",IF(F11>=3,"Medium (3-4)","Small (1-2)")) -> Small (1-2) | Q11: =IF(K11="Completed",1,0) -> 0 | R11: =IF(K11="Cancelled",1,0) -> 1 | S11: =IF(K11="Cancelled",G11,0) -> 500
A12: ORD0011 | B12: 45705 | C12: Book | D12: Books | E12: 15 | F12: 2 | G12: 30 | H12: David Lee | I12: Boston | J12: Amazon Pay | K12: Pending | L12: =TEXT(B12,"MMMM") -> February | M12: =MONTH(B12) -> 2 | N12: =IF(MONTH(B12)<=3,"Q1",IF(MONTH(B12)<=6,"Q2",IF(MONTH(B12)<=9,"Q3","Q4"))) -> Q1 | O12: =IF(G12>=5000,"High (≥5K)",IF(G12>=2000,"Mid (2K-5K)","Low (<2K)")) -> Low (<2K) | P12: =IF(F12>=5,"Bulk (5+)",IF(F12>=3,"Medium (3-4)","Small (1-2)")) -> Small (1-2) | Q12: =IF(K12="Completed",1,0) -> 0 | R12: =IF(K12="Cancelled",1,0) -> 0 | S12: =IF(K12="Cancelled",G12,0) -> 0
A13: ORD0012 | B13: 45729 | C13: Jeans | D13: Clothing | E13: 40 | F13: 4 | G13: 160 | H13: Michael Brown | I13: Dallas | J13: Credit Card | K13: Completed | L13: =TEXT(B13,"MMMM") -> March | M13: =MONTH(B13) -> 3 | N13: =IF(MONTH(B13)<=3,"Q1",IF(MONTH(B13)<=6,"Q2",IF(MONTH(B13)<=9,"Q3","Q4"))) -> Q1 | O13: =IF(G13>=5000,"High (≥5K)",IF(G13>=2000,"Mid (2K-5K)","Low (<2K)")) -> Low (<2K) | P13: =IF(F13>=5,"Bulk (5+)",IF(F13>=3,"Medium (3-4)","Small (1-2)")) -> Medium (3-4) | Q13: =IF(K13="Completed",1,0) -> 1 | R13: =IF(K13="Cancelled",1,0) -> 0 | S13: =IF(K13="Cancelled",G13,0) -> 0
... A251: ORD0250 | B251: 45707 | C251: Smartphone | D251: Electronics | E251: 500 | F251: 4 | G251: 2000 | H251: Emily Johnson | I251: Seattle | J251: Amazon Pay | K251: Completed | L251: =TEXT(B251,"MMMM") -> February | M251: =MONTH(B251) -> 2 | N251: =IF(MONTH(B251)<=3,"Q1",IF(MONTH(B251)<=6,"Q2",IF(MONTH(B251)<=9,"Q3","Q4"))) -> Q1 | O251: =IF(G251>=5000,"High (≥5K)",IF(G251>=2000,"Mid (2K-5K)","Low (<2K)")) -> Mid (2K-5K) | P251: =IF(F251>=5,"Bulk (5+)",IF(F251>=3,"Medium (3-4)","Small (1-2)")) -> Medium (3-4) | Q251: =IF(K251="Completed",1,0) -> 1 | R251: =IF(K251="Cancelled",1,0) -> 0 | S251: =IF(K251="Cancelled",G251,0) -> 0

Sheet Data Validation
A1: Total rows = 250 | B1: =COUNTA('amazon_sales_data 2025'!A:A)-1 -> 250
A2: No duplicate Order IDs | B2: Remove Duplicates on Order ID column
A3: Date column is proper date format | B3: Format Cells → Date
A4: Total Sales = Price × Quantity | B4: ='amazon_sales_data 2025'!E2*'amazon_sales_data 2025'!F2='amazon_sales_data 2025'!G2 -> TRUE
A5: No blank Status values | B5: =COUNTBLANK('amazon_sales_data 2025'!K2:K251) -> 0
A6: Status only has 3 valid values | B6: =COUNTIFS('amazon_sales_data 2025'!K2:K251,"<>Completed",'amazon_sales_data 2025'!K2:K251,"<>Pending",'amazon_sales_data 2025'!K2:K251,"<>Cancelled") -> 0

Sheet KPI's & Pivot
B1: Total Revenue | C1: Total Orders | D1: Completion Rate | E1: Cancellation Rate | F1: Avg Order Value | G1: Revenue Lost to Cancellations | H1: Top Category by Revenue
B2: =SUMIF(Table1[Status],"Completed",Table1[Total Sales]) -> 88530 | C2: {=COUNTA(Table1[Order ID]-1)} -> 250 | D2: =COUNTIF(Table1[Status],"Completed")/COUNTA(Table1[Order ID]) -> 0.352 | E2: =COUNTIF(Table1[Status],"Cancelled")/COUNTA(Table1[Order ID]) -> 0.308 | F2: =AVERAGEIF(Table1[Status],"Completed",Table1[Total Sales]) -> 1006.0227 | G2: =SUMIF(Table1[Status],"Completed",Table1[Total Sales]) -> 88530 | H2: {=INDEX(Table1[Category],MATCH(MAX(SUMIF(Table1[Category],Table1[Category],Table1[Total Sales])),SUMIF(Table1[Category],Table1[Category],Table1[Total Sales]),0))} -> Electronics
A3: Best Month
A4: Row Labels | B4: Sum of Total Sales
A5: February | B5: 122695
A6: March | B6: 117730
A7: April | B7: 3420
A8: Grand Total | B8: 243845
A10: Monthly Revenue Trend
A11: Row Labels | B11: Sum of Total Sales | C11: Count of Orders
A12: February | B12: 122695 | C12: 113
A13: March | B13: 117730 | C13: 131
A14: April | B14: 3420 | C14: 6
A15: Grand Total | B15: 243845 | C15: 250
A17: Revenue by Category
A18: Row Labels | B18: Sum of Total Sales | C18: Average of Price
A19: Electronics | B19: 129950 | C19: 375.42373
A20: Home Appliances | B20: 105000 | C20: 960
A21: Footwear | B21: 4320 | C21: 60
A22: Clothing | B22: 3540 | C22: 30
A23: Books | B23: 1035 | C23: 15
A24: Grand Total | B24: 243845 | C24: 343.58
A26: Order Status Breakdown
A27: Row Labels | B27: Sum of Total Sales2
A28: Cancelled | B28: 0.2666858
A29: Completed | B29: 0.3630585
A30: Pending | B30: 0.3702557
A31: Grand Total | B31: 1
A33: Revenue by Customer Location (City)
A34: Row Labels | B34: Sum of Total Sales
A35: Miami | B35: 31700
A36: Denver | B36: 29785
A37: Houston | B37: 28390
A38: Dallas | B38: 27145
A39: Seattle | B39: 26890
A40: Boston | B40: 26170
A41: Chicago | B41: 20810
A42: New York | B42: 18940
A43: Los Angeles | B43: 17820
A44: San Francisco | B44: 16195
...

Sheet Key Analysis
A1: Cancellation Leakage Analysis | F1: Payment Method vs. Completion Rate | L1: Avg Order Value by Category
A2: =SUMIF('amazon_sales_data 2025'!K2:K251,"Cancelled",'amazon_sales_data 2025'!G2:G251) -> 65030 | F2: =COUNTIFS('amazon_sales_data 2025'!J2:J251,"Credit Card",'amazon_sales_data 2025'!K2:K251,"Completed")/COUNTIFS('amazon_sales_data 2025'!J2:J251,"Credit Card",'amazon_sales_data 2025'!K2:K251,"<>") -> 0.31481481 | L2: =AVERAGEIF('amazon_sales_data 2025'!D2:D251,"Electronics",'amazon_sales_data 2025'!G2:G251) -> 1101.2712
A3: Category | B3: Revenue Loss | C3: AOV | D3: Orders | E3: Cancellation Count
A4: {=_xlfn.UNIQUE(Table1[Category])} -> Footwear | B4: =SUMIFS(Table1[Total Sales],Table1[Category],'Key Analysis'!A4,Table1[Status],"Cancelled") -> 1080 | C4: =AVERAGEIF('amazon_sales_data 2025'!D2:D251,A4,'amazon_sales_data 2025'!G2:G251) -> 160 | D4: =SUMIF(Table1[Category],A4,Table1[Quantity]) -> 72 | E4: =SUMIF(Table1[Status],"Cancelled",Table1[Total Sales]) -> 65030
A5: Electronics | B5: =SUMIFS(Table1[Total Sales],Table1[Category],'Key Analysis'!A5,Table1[Status],"Cancelled") -> 26650 | C5: =AVERAGEIF('amazon_sales_data 2025'!D3:D252,A5,'amazon_sales_data 2025'!G2:G252) -> 827.92373 | D5: =SUMIF(Table1[Category],A5,Table1[Quantity]) -> 348 | E5: =SUMIF(Table1[Status],"Cancelled",Table1[Total Sales]) -> 65030
A6: Clothing | B6: =SUMIFS(Table1[Total Sales],Table1[Category],'Key Analysis'!A6,Table1[Status],"Cancelled") -> 1120 | C6: =AVERAGEIF('amazon_sales_data 2025'!D4:D253,A6,'amazon_sales_data 2025'!G2:G253) -> 819.75 | D6: =SUMIF(Table1[Category],A6,Table1[Quantity]) -> 115 | E6: =SUMIF(Table1[Status],"Cancelled",Table1[Total Sales]) -> 65030
A7: Books | B7: =SUMIFS(Table1[Total Sales],Table1[Category],'Key Analysis'!A7,Table1[Status],"Cancelled") -> 180 | C7: =AVERAGEIF('amazon_sales_data 2025'!D5:D254,A7,'amazon_sales_data 2025'!G2:G254) -> 1400.8 | D7: =SUMIF(Table1[Category],A7,Table1[Quantity]) -> 69 | E7: =SUMIF(Table1[Status],"Cancelled",Table1[Total Sales]) -> 65030
A8: Home Appliances | B8: =SUMIFS(Table1[Total Sales],Table1[Category],'Key Analysis'!A8,Table1[Status],"Cancelled") -> 36000 | C8: =AVERAGEIF('amazon_sales_data 2025'!D6:D255,A8,'amazon_sales_data 2025'!G2:G255) -> 931.25 | D8: =SUMIF(Table1[Category],A8,Table1[Quantity]) -> 110 | E8: =SUMIF(Table1[Status],"Cancelled",Table1[Total Sales]) -> 65030

Sheet Dashboard
A1: Revenue & Order Performance Dashboard - 2025

Sheet Revenue MIS Report
A1: Revenue & Order Performance Dashboard - 2025
A5: Category Performance
A6: Category | B6: Total Orders | C6: Completed Orders | D6: Cancelled Orders | E6: Pending Orders | F6: Total Revenue (₹) | G6: Completed Revenue (₹) | H6: Revenue Lost to Cancellations (₹) | I6: Avg Order Value (₹) | J6: Completion Rate | K6: Cancellation Rate | L6: Insight
A7: {=_xlfn.UNIQUE(Table1[Category])} -> Footwear | B7: =COUNTIF(Table1[Category], 'Revenue MIS Report'!A7) -> 27 | C7: =COUNTIFS(Table1[Category], A7, Table1[Status], "Completed") -> 10 | D7: =COUNTIFS(Table1[Category], A7, Table1[Status], "Cancelled") -> 8 | E7: =COUNTIFS(Table1[Category], A7, Table1[Status], "Pending") -> 9 | F7: =SUMIF(Table1[Category], A7, Table1[Total Sales]) -> 4320 | G7: =SUMIFS(Table1[Total Sales], Table1[Category], A7, Table1[Status], "Completed") -> 1620 | H7: =SUMIFS(Table1[Total Sales], Table1[Category], A7, Table1[Status], "Cancelled") -> 1080 | I7: =AVERAGEIF('amazon_sales_data 2025'!D2:D251,A7,'amazon_sales_data 2025'!G2:G251) -> 160 | J7: =C7/B7 -> 0.37037037 | K7: =D7/B7 -> 0.2962963 | L7: Highest cancellation rate at 30% — quality or sizing expectation mismatch; review return reasons
A8: Electronics | B8: =COUNTIF(Table1[Category], 'Revenue MIS Report'!A8) -> 118 | C8: =COUNTIFS(Table1[Category], A8, Table1[Status], "Completed") -> 44 | D8: =COUNTIFS(Table1[Category], A8, Table1[Status], "Cancelled") -> 33 | E8: =COUNTIFS(Table1[Category], A8, Table1[Status], "Pending") -> 41 | F8: =SUMIF(Table1[Category], A8, Table1[Total Sales]) -> 129950 | G8: =SUMIFS(Table1[Total Sales], Table1[Category], A8, Table1[Status], "Completed") -> 55900 | H8: =SUMIFS(Table1[Total Sales], Table1[Category], A8, Table1[Status], "Cancelled") -> 26650 | I8: =AVERAGEIF('amazon_sales_data 2025'!D3:D252,A8,'amazon_sales_data 2025'!G2:G252) -> 827.92373 | J8: =C8/B8 -> 0.37288136 | K8: =D8/B8 -> 0.27966102 | L8: Largest category by orders (118) and revenue (₹1,29,950); 28% cancellation rate needs attention — highest revenue at risk
A9: Clothing | B9: =COUNTIF(Table1[Category], 'Revenue MIS Report'!A9) -> 40 | C9: =COUNTIFS(Table1[Category], A9, Table1[Status], "Completed") -> 15 | D9: =COUNTIFS(Table1[Category], A9, Table1[Status], "Cancelled") -> 13 | E9: =COUNTIFS(Table1[Category], A9, Table1[Status], "Pending") -> 12 | F9: =SUMIF(Table1[Category], A9, Table1[Total Sales]) -> 3540 | G9: =SUMIFS(Table1[Total Sales], Table1[Category], A9, Table1[Status], "Completed") -> 1400 | H9: =SUMIFS(Table1[Total Sales], Table1[Category], A9, Table1[Status], "Cancelled") -> 1120 | I9: =AVERAGEIF('amazon_sales_data 2025'!D4:D253,A9,'amazon_sales_data 2025'!G2:G253) -> 819.75 | J9: =C9/B9 -> 0.375 | K9: =D9/B9 -> 0.325 | L9: 33% cancellation rate — worst performer; likely fit/size issues; consider size guide improvement
A10: Books | B10: =COUNTIF(Table1[Category], 'Revenue MIS Report'!A10) -> 25 | C10: =COUNTIFS(Table1[Category], A10, Table1[Status], "Completed") -> 6 | D10: =COUNTIFS(Table1[Category], A10, Table1[Status], "Cancelled") -> 7 | E10: =COUNTIFS(Table1[Category], A10, Table1[Status], "Pending") -> 12 | F10: =SUMIF(Table1[Category], A10, Table1[Total Sales]) -> 1035 | G10: =SUMIFS(Table1[Total Sales], Table1[Category], A10, Table1[Status], "Completed") -> 210 | H10: =SUMIFS(Table1[Total Sales], Table1[Category], A10, Table1[Status], "Cancelled") -> 180 | I10: =AVERAGEIF('amazon_sales_data 2025'!D5:D254,A10,'amazon_sales_data 2025'!G2:G254) -> 1400.8 | J10: =C10/B10 -> 0.24 | K10: =D10/B10 -> 0.28 | L10: Smallest revenue (₹1,035); cancellation at 28% — most reliable category; scale assortment
A11: Home Appliances | B11: =COUNTIF(Table1[Category], 'Revenue MIS Report'!A11) -> 40 | C11: =COUNTIFS(Table1[Category], A11, Table1[Status], "Completed") -> 13 | D11: =COUNTIFS(Table1[Category], A11, Table1[Status], "Cancelled") -> 16 | E11: =COUNTIFS(Table1[Category], A11, Table1[Status], "Pending") -> 11 | F11: =SUMIF(Table1[Category], A11, Table1[Total Sales]) -> 105000 | G11: =SUMIFS(Table1[Total Sales], Table1[Category], A11, Table1[Status], "Completed") -> 29400 | H11: =SUMIFS(Table1[Total Sales], Table1[Category], A11, Table1[Status], "Cancelled") -> 36000 | I11: =AVERAGEIF('amazon_sales_data 2025'!D6:D255,A11,'amazon_sales_data 2025'!G2:G255) -> 931.25 | J11: =C11/B11 -> 0.325 | K11: =D11/B11 -> 0.4 | L11: 40% cancellation rate — highest across all categories; urgent investigation needed; delivery or product quality issue
A12: Grand Total | B12: =SUM(B7:B11) -> 250 | C12: =SUM(C7:C11) -> 88 | D12: =SUM(D7:D11) -> 77 | E12: =SUM(E7:E11) -> 85 | F12: =SUM(F7:F11) -> 243845 | G12: =SUM(G7:G11) -> 88530 | H12: =SUM(H7:H11) -> 65030 | I12: =SUM(I7:I11) -> 4139.7237
A14: ₹65,030 total revenue lost to cancellations — 26.7% of gross revenue. Home Appliances and Clothing are the primary leakage drivers.
A17: Monthly Performance
A18: Months | B18: Total Orders | C18: Total Revenue (₹) | D18: Completed Revenue (₹) | E18: Completed Orders | F18: Avg Order Value (₹) | G18: MoM Revenue Change (₹) | H18: MoM Growth % | I18: Running Total Revenue (Cumulative)
A19: February | B19: =COUNTIF(Table1[Month],A19) -> 113 | C19: =SUMIF(Table1[Month],'Revenue MIS Report'!A19,Table1[Total Sales]) -> 122695 | D19: =SUMIFS(Table1[Total Sales], Table1[Month], A19, Table1[Status], "Completed") -> 40865 | E19: =COUNTIFS(Table1[Month], A19, Table1[Status], "Completed") -> 36 | F19: =D19/E19 -> 1135.1389 | G19: NA | H19: NA | I19: =SUM($C$19:C19) -> 122695
A20: March | B20: =COUNTIF(Table1[Month],A20) -> 131 | C20: =SUMIF(Table1[Month],'Revenue MIS Report'!A20,Table1[Total Sales]) -> 117730 | D20: =SUMIFS(Table1[Total Sales], Table1[Month], A20, Table1[Status], "Completed") -> 45145 | E20: =COUNTIFS(Table1[Month], A20, Table1[Status], "Completed") -> 49 | F20: =D20/E20 -> 921.32653 | G20: =D20-D19 -> 4280 | H20: =G20/D19 -> 0.1047351 | I20: =SUM($C$19:C20) -> 240425
A21: April | B21: =COUNTIF(Table1[Month],A21) -> 6 | C21: =SUMIF(Table1[Month],'Revenue MIS Report'!A21,Table1[Total Sales]) -> 3420 | D21: =SUMIFS(Table1[Total Sales], Table1[Month], A21, Table1[Status], "Completed") -> 2520 | E21: =COUNTIFS(Table1[Month], A21, Table1[Status], "Completed") -> 3 | F21: =D21/E21 -> 840 | G21: =D21-D20 -> -42625 | H21: =G21/D20 -> -0.94417986 | I21: =SUM($C$19:C21) -> 243845
A22: Grand Total | B22: =SUM(B19:B21) -> 250 | C22: =SUM(C19:C21) -> 243845 | D22: =SUM(D19:D21) -> 88530 | E22: =SUM(E19:E21) -> 88 | F22: =SUM(F19:F21) -> 2896.4654
A25: Payment Method Analysis
A26: Payment Method | B26: Total Orders | C26: % of Total Orders | D26: Total Revenue (₹) | E26: Avg Order Value (₹) | F26: Completed Orders | G26: Completion Rate | H26: Cancelled Orders | I26: Cancellation Rate | J26: Insight
A27: {=_xlfn.UNIQUE(Table1[Payment Method])} -> Debit Card | B27: =COUNTIF(Table1[Payment Method],'Revenue MIS Report'!A27) -> 53 | C27: =B27/$B$32 -> 0.212 | D27: =SUMIF(Table1[Payment Method],'Revenue MIS Report'!A27,Table1[Total Sales]) -> 31900 | E27: =AVERAGEIF(Table1[Payment Method],'Revenue MIS Report'!A27,Table1[Total Sales]) -> 601.88679 | F27: =COUNTIFS(Table1[Payment Method], A27, Table1[Status], "Completed") -> 14 | G27: =F27/$F$32 -> 0.15909091 | H27: =COUNTIFS(Table1[Payment Method], A27, Table1[Status], "Cancelled") -> 20 | I27: =H27/$H$32 -> 0.25974026 | J27: Lowest completion rate at 15.91% with 26% cancellation — highest risk payment method; may indicate impulsive buying
A28: Amazon Pay | B28: =COUNTIF(Table1[Payment Method],'Revenue MIS Report'!A28) -> 41 | C28: =B28/$B$32 -> 0.164 | D28: =SUMIF(Table1[Payment Method],'Revenue MIS Report'!A28,Table1[Total Sales]) -> 32750 | E28: =AVERAGEIF(Table1[Payment Method],'Revenue MIS Report'!A28,Table1[Total Sales]) -> 798.78049 | F28: =COUNTIFS(Table1[Payment Method], A28, Table1[Status], "Completed") -> 21 | G28: =F28/$F$32 -> 0.23863636 | H28: =COUNTIFS(Table1[Payment Method], A28, Table1[Status], "Cancelled") -> 7 | I28: =H28/$H$32 -> 0.090909091 | J28: Best completion rate at 23.86% with only 9% cancellation — most reliable payment channel; promote this option
A29: Credit Card | B29: =COUNTIF(Table1[Payment Method],'Revenue MIS Report'!A29) -> 54 | C29: =B29/$B$32 -> 0.216 | D29: =SUMIF(Table1[Payment Method],'Revenue MIS Report'!A29,Table1[Total Sales]) -> 61595 | E29: =AVERAGEIF(Table1[Payment Method],'Revenue MIS Report'!A29,Table1[Total Sales]) -> 1140.6481 | F29: =COUNTIFS(Table1[Payment Method], A29, Table1[Status], "Completed") -> 17 | G29: =F29/$F$32 -> 0.19318182 | H29: =COUNTIFS(Table1[Payment Method], A29, Table1[Status], "Cancelled") -> 16 | I29: =H29/$H$32 -> 0.20779221 | J29: 19.32% completion, 21% cancellation — mid-tier; high avg order value (₹1,140) suggests premium buyers
A30: PayPal | B30: =COUNTIF(Table1[Payment Method],'Revenue MIS Report'!A30) -> 60 | C30: =B30/$B$32 -> 0.24 | D30: =SUMIF(Table1[Payment Method],'Revenue MIS Report'!A30,Table1[Total Sales]) -> 69645 | E30: =AVERAGEIF(Table1[Payment Method],'Revenue MIS Report'!A30,Table1[Total Sales]) -> 1160.75 | F30: =COUNTIFS(Table1[Payment Method], A30, Table1[Status], "Completed") -> 30 | G30: =F30/$F$32 -> 0.34090909 | H30: =COUNTIFS(Table1[Payment Method], A30, Table1[Status], "Cancelled") -> 16 | I30: =H30/$H$32 -> 0.20779221 | J30: Highest order count (60) and highest total revenue (₹69,645); 34% completion rate — volume leader but reliability concern
A31: Gift Card | B31: =COUNTIF(Table1[Payment Method],'Revenue MIS Report'!A31) -> 42 | C31: =B31/$B$32 -> 0.168 | D31: =SUMIF(Table1[Payment Method],'Revenue MIS Report'!A31,Table1[Total Sales]) -> 47955 | E31: =AVERAGEIF(Table1[Payment Method],'Revenue MIS Report'!A31,Table1[Total Sales]) -> 1141.7857 | F31: =COUNTIFS(Table1[Payment Method], A31, Table1[Status], "Completed") -> 6 | G31: =F31/$F$32 -> 0.068181818 | H31: =COUNTIFS(Table1[Payment Method], A31, Table1[Status], "Cancelled") -> 18 | I31: =H31/$H$32 -> 0.23376623 | J31: Lowest completion rate at 6.82% — gift card orders rarely complete; investigate redemption flow
A32: Grand Total | B32: =SUM(B27:B31) -> 250 | D32: =SUM(D27:D31) -> 243845 | E32: =SUM(E27:E31) -> 4843.8511 | F32: =SUM(F27:F31) -> 88 | H32: =SUM(H27:H31) -> 77
A34: Amazon Pay has the lowest cancellation rate (9%) despite mid-range order volume — recommend making it the default payment option at checkout.
A37: City / Location Performance
A38: City | B38: Total Orders | C38: Total Revenue (₹) | D38: % of Total Revenue | E38: Avg Order Value (₹) | F38: Cancellation Rate | G38: Rank | H38: Insight
A39: {=_xlfn.UNIQUE(Table1[Customer Location])} -> New York | B39: =COUNTIF(Table1[Customer Location],'Revenue MIS Report'!A39) -> 26 | C39: =SUMIF(Table1[Customer Location],'Revenue MIS Report'!A39,Table1[Total Sales]) -> 18940 | D39: =C39/$C$49 -> 0.077672292 | E39: =AVERAGEIF(Table1[Customer Location],'Revenue MIS Report'!A39,Table1[Total Sales]) -> 728.46154 | F39: =COUNTIFS(Table1[Customer Location],'Revenue MIS Report'!A39,Table1[Status],"Cancelled")/COUNTIF(Table1[Customer Location],'Revenue MIS Report'!A39) -> 0.34615385 | G39: =RANK(C39,$C$39:$C$48,0) -> 8 | H39: Ranked 8th despite 26 orders; low avg order value (₹728) — price-sensitive market; target with budget promotions
A40: San Francisco | B40: =COUNTIF(Table1[Customer Location],'Revenue MIS Report'!A40) -> 19 | C40: =SUMIF(Table1[Customer Location],'Revenue MIS Report'!A40,Table1[Total Sales]) -> 16195 | D40: =C40/$C$49 -> 0.066415141 | E40: =AVERAGEIF(Table1[Customer Location],'Revenue MIS Report'!A40,Table1[Total Sales]) -> 852.36842 | F40: =COUNTIFS(Table1[Customer Location],'Revenue MIS Report'!A40,Table1[Status],"Cancelled")/COUNTIF(Table1[Customer Location],'Revenue MIS Report'!A40) -> 0.15789474 | G40: =RANK(C40,$C$39:$C$48,0) -> 10 | H40: Ranked 10th; lowest order count (19) but decent avg value (₹852) — low penetration market; growth opportunity
A41: Denver | B41: =COUNTIF(Table1[Customer Location],'Revenue MIS Report'!A41) -> 26 | C41: =SUMIF(Table1[Customer Location],'Revenue MIS Report'!A41,Table1[Total Sales]) -> 29785 | D41: =C41/$C$49 -> 0.12214727 | E41: =AVERAGEIF(Table1[Customer Location],'Revenue MIS Report'!A41,Table1[Total Sales]) -> 1145.5769 | F41: =COUNTIFS(Table1[Customer Location],'Revenue MIS Report'!A41,Table1[Status],"Cancelled")/COUNTIF(Table1[Customer Location],'Revenue MIS Report'!A41) -> 0.34615385 | G41: =RANK(C41,$C$39:$C$48,0) -> 2 | H41: Ranked 2nd by revenue (₹29,785); 35% cancellation rate — high value but unreliable; investigate delivery issues
A42: Dallas | B42: =COUNTIF(Table1[Customer Location],'Revenue MIS Report'!A42) -> 29 | C42: =SUMIF(Table1[Customer Location],'Revenue MIS Report'!A42,Table1[Total Sales]) -> 27145 | D42: =C42/$C$49 -> 0.11132072 | E42: =AVERAGEIF(Table1[Customer Location],'Revenue MIS Report'!A42,Table1[Total Sales]) -> 936.03448 | F42: =COUNTIFS(Table1[Customer Location],'Revenue MIS Report'!A42,Table1[Status],"Cancelled")/COUNTIF(Table1[Customer Location],'Revenue MIS Report'!A42) -> 0.37931034 | G42: =RANK(C42,$C$39:$C$48,0) -> 4 | H42: Ranked 4th; highest cancellation rate at 38% — significant revenue leakage; operational review needed
A43: Houston | B43: =COUNTIF(Table1[Customer Location],'Revenue MIS Report'!A43) -> 32 | C43: =SUMIF(Table1[Customer Location],'Revenue MIS Report'!A43,Table1[Total Sales]) -> 28390 | D43: =C43/$C$49 -> 0.11642642 | E43: =AVERAGEIF(Table1[Customer Location],'Revenue MIS Report'!A43,Table1[Total Sales]) -> 887.1875 | F43: =COUNTIFS(Table1[Customer Location],'Revenue MIS Report'!A43,Table1[Status],"Cancelled")/COUNTIF(Table1[Customer Location],'Revenue MIS Report'!A43) -> 0.21875 | G43: =RANK(C43,$C$39:$C$48,0) -> 3 | H43: Ranked 3rd by revenue (₹28,390); balanced 22% cancellation — most consistent high-revenue city
A44: Miami | B44: =COUNTIF(Table1[Customer Location],'Revenue MIS Report'!A44) -> 31 | C44: =SUMIF(Table1[Customer Location],'Revenue MIS Report'!A44,Table1[Total Sales]) -> 31700 | D44: =C44/$C$49 -> 0.13000062 | E44: =AVERAGEIF(Table1[Customer Location],'Revenue MIS Report'!A44,Table1[Total Sales]) -> 1022.5806 | F44: =COUNTIFS(Table1[Customer Location],'Revenue MIS Report'!A44,Table1[Status],"Cancelled")/COUNTIF(Table1[Customer Location],'Revenue MIS Report'!A44) -> 0.38709677 | G44: =RANK(C44,$C$39:$C$48,0) -> 1 | H44: Ranked 1st by revenue (₹31,700); 39% cancellation rate — top city but highest cancellation risk; priority for retention
A45: Boston | B45: =COUNTIF(Table1[Customer Location],'Revenue MIS Report'!A45) -> 26 | C45: =SUMIF(Table1[Customer Location],'Revenue MIS Report'!A45,Table1[Total Sales]) -> 26170 | D45: =C45/$C$49 -> 0.10732227 | E45: =AVERAGEIF(Table1[Customer Location],'Revenue MIS Report'!A45,Table1[Total Sales]) -> 1006.5385 | F45: =COUNTIFS(Table1[Customer Location],'Revenue MIS Report'!A45,Table1[Status],"Cancelled")/COUNTIF(Table1[Customer Location],'Revenue MIS Report'!A45) -> 0.26923077 | G45: =RANK(C45,$C$39:$C$48,0) -> 6 | H45: Ranked 6th; 27% cancellation — mid-performer; avg order value (₹1,006) above average
A46: Seattle | B46: =COUNTIF(Table1[Customer Location],'Revenue MIS Report'!A46) -> 22 | C46: =SUMIF(Table1[Customer Location],'Revenue MIS Report'!A46,Table1[Total Sales]) -> 26890 | D46: =C46/$C$49 -> 0.11027497 | E46: =AVERAGEIF(Table1[Customer Location],'Revenue MIS Report'!A46,Table1[Total Sales]) -> 1222.2727 | F46: =COUNTIFS(Table1[Customer Location],'Revenue MIS Report'!A46,Table1[Status],"Cancelled")/COUNTIF(Table1[Customer Location],'Revenue MIS Report'!A46) -> 0.22727273 | G46: =RANK(C46,$C$39:$C$48,0) -> 5 | H46: Ranked 5th; lowest cancellation at 23% among top cities; highest avg order value (₹1,222) — premium market
A47: Los Angeles | B47: =COUNTIF(Table1[Customer Location],'Revenue MIS Report'!A47) -> 17 | C47: =SUMIF(Table1[Customer Location],'Revenue MIS Report'!A47,Table1[Total Sales]) -> 17820 | D47: =C47/$C$49 -> 0.07307921 | E47: =AVERAGEIF(Table1[Customer Location],'Revenue MIS Report'!A47,Table1[Total Sales]) -> 1048.2353 | F47: =COUNTIFS(Table1[Customer Location],'Revenue MIS Report'!A47,Table1[Status],"Cancelled")/COUNTIF(Table1[Customer Location],'Revenue MIS Report'!A47) -> 0.52941176 | G47: =RANK(C47,$C$39:$C$48,0) -> 9 | H47: 53% cancellation rate — worst city performance; only 17 orders but more than half cancel; urgent review
A48: Chicago | B48: =COUNTIF(Table1[Customer Location],'Revenue MIS Report'!A48) -> 22 | C48: =SUMIF(Table1[Customer Location],'Revenue MIS Report'!A48,Table1[Total Sales]) -> 20810 | D48: =C48/$C$49 -> 0.085341098 | E48: =AVERAGEIF(Table1[Customer Location],'Revenue MIS Report'!A48,Table1[Total Sales]) -> 945.90909 | F48: =COUNTIFS(Table1[Customer Location],'Revenue MIS Report'!A48,Table1[Status],"Cancelled")/COUNTIF(Table1[Customer Location],'Revenue MIS Report'!A48) -> 0.22727273 | G48: =RANK(C48,$C$39:$C$48,0) -> 7 | H48: Ranked 7th; 23% cancellation — stable performer; growth potential with targeted campaigns
A49: Grand Total | B49: =SUM(B39:B48) -> 250 | C49: =SUM(C39:C48) -> 243845 | E49: =SUM(E39:E48) -> 9795.1651
A51: Seattle has the highest avg order value (₹1,222) with the most reliable completion rate among top cities — ideal market for premium product launches. Los Angeles has a 53% cancellation rate and should be flagged for immediate operational review.
